Workbook
Name Себестоимость: [1]Справочник!$C$3:$C$6
Name Себестоимость: Справочник!$C$3:$C$6
Name Capex_группы_СПП: [1]Справочник!$A$3:$A$26
Name Capex_группы_СПП: Справочник!$A$3:$A$25
Name Language: [2]Outputs!$AU$1
Name OPEX_группы_СПП: [1]Справочник!$B$3:$B$15
Name OPEX_группы_СПП: Справочник!$B$3:$B$15
Name OPEX_PL: Справочник!$D$3:$D$15
Name SAPCrosstab1: #REF!
Name SAPFdd1: #REF!
Name SAPFdd10: #REF!
Name SAPFdd11: #REF!
Name SAPFdd12: #REF!
Name SAPFdd13: #REF!
Name SAPFdd14: #REF!
Name SAPFdd15: #REF!
Name SAPFdd16: #REF!
Name SAPFdd17: #REF!
Name SAPFdd18: #REF!
Name SAPFdd2: #REF!
Name SAPFdd29: #REF!
Name SAPFdd3: #REF!
Name SAPFdd30: #REF!
Name SAPFdd31: #REF!
Name SAPFdd32: #REF!
Name SAPFdd33: #REF!
Name SAPFdd34: #REF!
Name SAPFdd35: #REF!
Name SAPFdd36: #REF!
Name SAPFdd37: #REF!
Name SAPFdd38: #REF!
Name SAPFdd39: #REF!
Name SAPFdd4: #REF!
Name SAPFdd40: #REF!
Name SAPFdd41: #REF!
Name SAPFdd5: #REF!
Name SAPFdd6: #REF!
Name SAPFdd7: #REF!
Name SAPFdd8: #REF!
Name SAPFdd9: #REF!
Name WORKBOOK_SAPBEXq0001: "DP_4"

Sheet Инструкция
B1: ЛЕГЕНДА
C2: Ячейки к заполнению значений / показателей
C3: Расчетные поля (не исправлять)
B5: ПРАВИЛА ДЛЯ КОРРЕКТНОЙ ЗАГРУЗКИ ШАБЛОНА НА ФИНАНСОВЫЙ ПОРТАЛ
B7: Финансовый портал для расчета показателей забирает данные только из вкладок "Как есть" и "Как будет". Поэтому правила корректной загрузки ТЭО на Финансовый портал применимы только к указанным вкладкам.
B8: 1. | C8: Нельзя добавлять новые строки, так как калькулятор Финансового портала настроен на определенный диапазон.
B9: 2. | C9: Нельзя вносить во всех голубых блоках отрицательные суммы (со знаком "-"), при сохранении шаблона калькулятор Финансового портала проигнорирует эти суммы. Рекомендуется учитывать отрицательные суммы в положительных суммах других месяцев в пределах одного года (например, при наличии суммы сторно в январе -100, ее следует "внести" в общую сумму в феврале: если в феврале было без сторно 500, с учетом сторно января станет 400)
B10: 3. | C10: Все значения в голубых полях на вкладках "Как есть" и "Как будет" заполняются строго БЕЗ ссылок на вспомогательные расчеты - Hard-значения (эффекты и затраты). Все необходимые детали по расчетам эффектов и затратам можно привести на дополнительной/вспомогательной вкладке.
B11: 4. | C11: Постпроектные расходы должны начинаться строго после даты Окончания проекта (ячейка D1).
B12: 5. | C12: Проектные расходы должны учитываться в диапазоне указанных Даты начала проекта (ячейка С1) и Даты окончания проекта (ячейка D1).
B13: 6. | C13: ВЕСЬ САРЕХ и ОРЕХ НА РЕАЛИЗАЦИЮ ПРОЕКТА должен "сидеть" в Проектных расходах, все что идет на тех поддержку после - в Постпроектных расходах, и ТОЛЬКО ЕСЛИ проект предполагает экономию на САРЕХ - это отражается в блоке с Экономическим эффектом. Блок "Экономический эффект" на Листе "Как есть" используется только для заполнения сумм эффекта по проекту/продукту, при условии, что ТЭО для проекта/продукта построен по принципу сравнения объема затрат или суммы дохода "До реализации проекта" (Как есть) и "После реализации проекта" (Как будет). Если эффект посчитан исключительно на дельте (уже посчитанная разница между Как есть и Как будет), то Лист "Как есть" не заполняется. ВАЖНО! После внесения данных на вкладки "Как есть" и "Как будет", обязательно проверить, что период начала инвестиций в проект (САРЕХ, ОРЕХ) наступает/закладывается ДО получения экономического эффекта от инициативы. Т.е. эффект от инициативы может быть получен только после момента старта проекта/продукта и вложения инвестиций.
B14: 7. | C14: Горизонт планирования определяется количеством месяцев, указанных в Сроке полезного использования (ячейка С7). Суммы, проставленные после последнего месяца горизонта планирования, калькулятор Финансового портала проигнорирует.
B15: 8. | C15: Привлечение дополнительной прибыли для Компании рассчитывается либо через ВАЛОВЫЙ ДОХОД, либо через КОММЕРЧЕСКУЮ МАРЖУ. Нельзя заполнять ОДНОВРЕМЕННО значения в строке Выручка/Себестоимость и Коммерческая маржа, т.к. Фин портал тогда рассматривает это как несколько доходных потоков и завышает IRR при сохранении на Финансовом портале.
B18: ПЕРВЫЕ ОБЯЗАТЕЛЬНЫЕ ШАГИ:
B20: 1. | C20: Указываем дату начала проекта/продукта на Листе "Как есть" в ячейке C1, в ячейке D1 - дату окончания проекта/продукта. Дата окончания проекта/продукта: окончание срока реализации внедряемого в рамках инициативы функционала = дата закрытия СПП (совпадает с датой завершения инвестиций в проект/продукт)
B22: 2. | C22: На Листе "Как есть" в ячейке C7 указываем в месяцах срок полезного использования оборудования (СПИ) или капитализируемого нематериалого актива (НМА), закупаемого/реализуемого в рамках проекта/продукта, на который будут рассчитываться показатели эффективности на вкладке "Свод"
B24: ! | C24: ИНФОРМАЦИЯ !
B25: Блок "Экономический эффект" на Листе "Как есть" используется только для заполнения сумм эффекта по проекту/продукту, при условии, что ТЭО для проекта/продукта построен по принципу сравнения объема затрат или суммы дохода "До реализации проекта" (Как есть) и "После реализации проекта" (Как будет). Если эффект посчитан исключительно на дельте (уже посчитанная разница между Как есть и Как будет), то Лист "Как есть" не заполняется.
B27: НАПОЛНЕНИЕ ТЭО ДАННЫМИ:
C29: Лист "Как есть"
B31: 3. | C31: Выбираем необходимые статьи в столбце A в зависимости от монетарного эффекта проекта/продукта:
C32: ● Экономия/снижение затрат
C33: → СAPEX или OPEX
C34: → СЕБЕСТОИМОСТЬ
C35: ● Привлечение дополнительной прибыли для Комании
C36: → ВЫРУЧКА помним, что Выручка - это РТО очищенный от НДС
C37: → ВАЛОВЫЙ ДОХОД помним, что Валовый доход - это Выручка за минусом Себестоимости товара
C38: → КОММЕРЧЕСКАЯ МАРЖА помним, что Коммерческая маржа - это сумма Front Margin и Back Margin
B40: 4. | C40: Наполняем диапазон ячеек C55:GT81 данными, в соответствии с выбранными статьями (столбец A) и периодами (строка 14) САРЕХ/ОРЕХ значения в голубых полях заполняются без знака "-" (положительное значение инвестиций/затрат), а также БЕЗ ссылок на вспомогательные расчеты
C41: Ячейки с серой заливкой в столбце B заполняются информационно для детализации данных.
C43: Лист "Как будет"
C45: Проектные расходы
B47: 5. | C47: Выбираем необходимые статьи затрат в столбце A в зависимости от вида затрат (CAPEX или OPEX)
B49: 6. | C49: Наполняем диапазон ячеек C17:GT33 данными, в соответствии с выбранными статьями (столбец A) и периодами (строка 14) САРЕХ/ОРЕХ значения в голубых полях заполняются без знака "-" (положительное значение инвестиций/затрат),а также без ссылок на вспомогательные расчеты
C50: Ячейки с серой заливкой в столбце B заполняются информационно для детализации данных.
C52: Постпроектные расходы Пост-проектные расходы - это затраты на тех. поддержку (после передачи проекта/продукта на тех. поддержку), последующие доработки действующих внедренных в рамках проекта/продукта систем и т.п. Постпроектные затраты начинаются не раньше даты окончания проекта/продукта/завершения основной фазы финансирования проекта/продукта (Лист "Как будет" ячейка D1). Постпроектные расходы (при их наличии) закладываются до конца горизонта планирования.
B54: 7. | C54: Выбираем необходимые статьи затрат в столбце A в зависимости от вида затрат (CAPEX или OPEX)
B56: 8. | C56: Наполняем диапазон ячеек C36:GT52 данными, в соответствии с выбранными статьями (столбец A) и периодами (строка 14) САРЕХ/ОРЕХ значения в голубых полях заполняются без знака "-" (положительное значение инвестиций/затрат),а также без ссылок на вспомогательные расчеты
C57: Ячейки с серой заливкой в столбце B заполняются информационно для детализации данных.
B58: ! | C58: Помним, что Постпроектные затраты начинаются не раньше даты окончания проекта/продукта (Лист "Как будет" ячейка D1) !
...

Sheet Свод
C1: =IF(C7<>0,1,0) -> 1 | D1: =IF(D7<>0,1,0) -> 1 | E1: =IF(E7<>0,1,0) -> 1 | F1: =IF(F7<>0,1,0) -> 1 | G1: =IF(G7<>0,1,0) -> 1 | H1: =IF(H7<>0,1,0) -> 0 | I1: =IF(I7<>0,1,0) -> 0
B2: Технико-экономическое обоснование | E2: Актуальный шаблон от 10.2025
B4: тыс. руб. | C4: ='Как есть'!C12 -> 2026 | D4: =C4+1 -> 2027 | E4: =D4+1 -> 2028 | F4: =E4+1 -> 2029 | G4: =F4+1 -> 2030 | H4: =G4+1 -> 2031 | I4: =H4+1 -> 2032 | J4: =I4+1 -> 2033 | K4: =J4+1 -> 2034 | ... M4: =L4+1 -> 2036
B5: Инфляция | C5: =HLOOKUP(C4,'Как есть'!$C$3:$S$5,2) -> 0.07 | D5: =HLOOKUP(D4,'Как есть'!$C$3:$S$5,2) -> 0.07 | E5: =HLOOKUP(E4,'Как есть'!$C$3:$S$5,2) -> 0.05 | F5: =HLOOKUP(F4,'Как есть'!$C$3:$S$5,2) -> 0.05 | G5: =HLOOKUP(G4,'Как есть'!$C$3:$S$5,2) -> 0.05 | H5: =HLOOKUP(H4,'Как есть'!$C$3:$S$5,2) -> 0.05 | I5: =HLOOKUP(I4,'Как есть'!$C$3:$S$5,2) -> 0.05 | J5: =HLOOKUP(J4,'Как есть'!$C$3:$S$5,2) -> 0.05 | ... M5: =HLOOKUP(M4,'Как есть'!$C$3:$S$5,2) -> 0.05
B6: Ставка дисконтирования (avg monthly WACC) | C6: =IFERROR(SUMIFS('Как будет'!5:5,'Как будет'!9:9,Свод!C4)/COUNTIFS('Как будет'!9:9,Свод!C4),Свод!B6) -> 0.16 | D6: =IFERROR(SUMIFS('Как будет'!5:5,'Как будет'!9:9,Свод!D4)/COUNTIFS('Как будет'!9:9,Свод!D4),Свод!C6) -> 0.16 | E6: =IFERROR(SUMIFS('Как будет'!5:5,'Как будет'!9:9,Свод!E4)/COUNTIFS('Как будет'!9:9,Свод!E4),Свод!D6) -> 0.16 | F6: =IFERROR(SUMIFS('Как будет'!5:5,'Как будет'!9:9,Свод!F4)/COUNTIFS('Как будет'!9:9,Свод!F4),Свод!E6) -> 0.16 | G6: =IFERROR(SUMIFS('Как будет'!5:5,'Как будет'!9:9,Свод!G4)/COUNTIFS('Как будет'!9:9,Свод!G4),Свод!F6) -> 0.16 | H6: =IFERROR(SUMIFS('Как будет'!5:5,'Как будет'!9:9,Свод!H4)/COUNTIFS('Как будет'!9:9,Свод!H4),Свод!G6) -> 0.16 | I6: =IFERROR(SUMIFS('Как будет'!5:5,'Как будет'!9:9,Свод!I4)/COUNTIFS('Как будет'!9:9,Свод!I4),Свод!H6) -> 0.16 | J6: =IFERROR(SUMIFS('Как будет'!5:5,'Как будет'!9:9,Свод!J4)/COUNTIFS('Как будет'!9:9,Свод!J4),Свод!I6) -> 0.16 | ... M6: =IFERROR(SUMIFS('Как будет'!5:5,'Как будет'!9:9,Свод!M4)/COUNTIFS('Как будет'!9:9,Свод!M4),Свод!L6) -> 0.16
A7: =SUM(C7:M7) -> 60 | B7: Кол-во месяцев | C7: =COUNTIF('Как есть'!12:12,Свод!C4) -> 12 | D7: =COUNTIF('Как есть'!12:12,Свод!D4) -> 12 | E7: =COUNTIF('Как есть'!12:12,Свод!E4) -> 12 | F7: =COUNTIF('Как есть'!12:12,Свод!F4) -> 12 | G7: =COUNTIF('Как есть'!12:12,Свод!G4) -> 12 | H7: =COUNTIF('Как есть'!12:12,Свод!H4) -> 0 | I7: =COUNTIF('Как есть'!12:12,Свод!I4) -> 0 | J7: =COUNTIF('Как есть'!12:12,Свод!J4) -> 0 | ... M7: =COUNTIF('Как есть'!12:12,Свод!M4) -> 0
B8: AS IS
B9: Проектные расходы
B10: Инвестиционная деятельность | C10: =SUMIF('Как есть'!$12:$12,Свод!C4,'Как есть'!$16:$16) -> 0 | D10: =SUMIF('Как есть'!$12:$12,Свод!D4,'Как есть'!$16:$16) -> 0 | E10: =SUMIF('Как есть'!$12:$12,Свод!E4,'Как есть'!$16:$16) -> 0 | F10: =SUMIF('Как есть'!$12:$12,Свод!F4,'Как есть'!$16:$16) -> 0 | G10: =SUMIF('Как есть'!$12:$12,Свод!G4,'Как есть'!$16:$16) -> 0 | H10: =SUMIF('Как есть'!$12:$12,Свод!H4,'Как есть'!$16:$16) -> 0 | I10: =SUMIF('Как есть'!$12:$12,Свод!I4,'Как есть'!$16:$16) -> 0 | J10: =SUMIF('Как есть'!$12:$12,Свод!J4,'Как есть'!$16:$16) -> 0 | ... M10: =SUMIF('Как есть'!$12:$12,Свод!M4,'Как есть'!$16:$16) -> 0
B11: Земельные участки | C11: =-SUMIF(Доп.расчеты!$3:$3,Свод!C$4,Доп.расчеты!110:110) -> 0 | D11: =-SUMIF(Доп.расчеты!$3:$3,Свод!D$4,Доп.расчеты!110:110) -> 0 | E11: =-SUMIF(Доп.расчеты!$3:$3,Свод!E$4,Доп.расчеты!110:110) -> 0 | F11: =-SUMIF(Доп.расчеты!$3:$3,Свод!F$4,Доп.расчеты!110:110) -> 0 | G11: =-SUMIF(Доп.расчеты!$3:$3,Свод!G$4,Доп.расчеты!110:110) -> 0 | H11: =-SUMIF(Доп.расчеты!$3:$3,Свод!H$4,Доп.расчеты!110:110) -> 0 | I11: =-SUMIF(Доп.расчеты!$3:$3,Свод!I$4,Доп.расчеты!110:110) -> 0 | J11: =-SUMIF(Доп.расчеты!$3:$3,Свод!J$4,Доп.расчеты!110:110) -> 0 | ... M11: =-SUMIF(Доп.расчеты!$3:$3,Свод!M$4,Доп.расчеты!110:110) -> 0
B12: Здания и сооружения | C12: =-SUMIF(Доп.расчеты!$3:$3,Свод!C$4,Доп.расчеты!111:111) -> 0 | D12: =-SUMIF(Доп.расчеты!$3:$3,Свод!D$4,Доп.расчеты!111:111) -> 0 | E12: =-SUMIF(Доп.расчеты!$3:$3,Свод!E$4,Доп.расчеты!111:111) -> 0 | F12: =-SUMIF(Доп.расчеты!$3:$3,Свод!F$4,Доп.расчеты!111:111) -> 0 | G12: =-SUMIF(Доп.расчеты!$3:$3,Свод!G$4,Доп.расчеты!111:111) -> 0 | H12: =-SUMIF(Доп.расчеты!$3:$3,Свод!H$4,Доп.расчеты!111:111) -> 0 | I12: =-SUMIF(Доп.расчеты!$3:$3,Свод!I$4,Доп.расчеты!111:111) -> 0 | J12: =-SUMIF(Доп.расчеты!$3:$3,Свод!J$4,Доп.расчеты!111:111) -> 0 | ... M12: =-SUMIF(Доп.расчеты!$3:$3,Свод!M$4,Доп.расчеты!111:111) -> 0
B13: Помещения в составе зданий и сооружений | C13: =-SUMIF(Доп.расчеты!$3:$3,Свод!C$4,Доп.расчеты!112:112) -> 0 | D13: =-SUMIF(Доп.расчеты!$3:$3,Свод!D$4,Доп.расчеты!112:112) -> 0 | E13: =-SUMIF(Доп.расчеты!$3:$3,Свод!E$4,Доп.расчеты!112:112) -> 0 | F13: =-SUMIF(Доп.расчеты!$3:$3,Свод!F$4,Доп.расчеты!112:112) -> 0 | G13: =-SUMIF(Доп.расчеты!$3:$3,Свод!G$4,Доп.расчеты!112:112) -> 0 | H13: =-SUMIF(Доп.расчеты!$3:$3,Свод!H$4,Доп.расчеты!112:112) -> 0 | I13: =-SUMIF(Доп.расчеты!$3:$3,Свод!I$4,Доп.расчеты!112:112) -> 0 | J13: =-SUMIF(Доп.расчеты!$3:$3,Свод!J$4,Доп.расчеты!112:112) -> 0 | ... M13: =-SUMIF(Доп.расчеты!$3:$3,Свод!M$4,Доп.расчеты!112:112) -> 0
B14: Строительство и ремонты | C14: =-SUMIF(Доп.расчеты!$3:$3,Свод!C$4,Доп.расчеты!113:113) -> 0 | D14: =-SUMIF(Доп.расчеты!$3:$3,Свод!D$4,Доп.расчеты!113:113) -> 0 | E14: =-SUMIF(Доп.расчеты!$3:$3,Свод!E$4,Доп.расчеты!113:113) -> 0 | F14: =-SUMIF(Доп.расчеты!$3:$3,Свод!F$4,Доп.расчеты!113:113) -> 0 | G14: =-SUMIF(Доп.расчеты!$3:$3,Свод!G$4,Доп.расчеты!113:113) -> 0 | H14: =-SUMIF(Доп.расчеты!$3:$3,Свод!H$4,Доп.расчеты!113:113) -> 0 | I14: =-SUMIF(Доп.расчеты!$3:$3,Свод!I$4,Доп.расчеты!113:113) -> 0 | J14: =-SUMIF(Доп.расчеты!$3:$3,Свод!J$4,Доп.расчеты!113:113) -> 0 | ... M14: =-SUMIF(Доп.расчеты!$3:$3,Свод!M$4,Доп.расчеты!113:113) -> 0
B15: Холодильное оборудование | C15: =-SUMIF(Доп.расчеты!$3:$3,Свод!C$4,Доп.расчеты!114:114) -> 0 | D15: =-SUMIF(Доп.расчеты!$3:$3,Свод!D$4,Доп.расчеты!114:114) -> 0 | E15: =-SUMIF(Доп.расчеты!$3:$3,Свод!E$4,Доп.расчеты!114:114) -> 0 | F15: =-SUMIF(Доп.расчеты!$3:$3,Свод!F$4,Доп.расчеты!114:114) -> 0 | G15: =-SUMIF(Доп.расчеты!$3:$3,Свод!G$4,Доп.расчеты!114:114) -> 0 | H15: =-SUMIF(Доп.расчеты!$3:$3,Свод!H$4,Доп.расчеты!114:114) -> 0 | I15: =-SUMIF(Доп.расчеты!$3:$3,Свод!I$4,Доп.расчеты!114:114) -> 0 | J15: =-SUMIF(Доп.расчеты!$3:$3,Свод!J$4,Доп.расчеты!114:114) -> 0 | ... M15: =-SUMIF(Доп.расчеты!$3:$3,Свод!M$4,Доп.расчеты!114:114) -> 0
B16: Стеллажное оборудование | C16: =-SUMIF(Доп.расчеты!$3:$3,Свод!C$4,Доп.расчеты!115:115) -> 0 | D16: =-SUMIF(Доп.расчеты!$3:$3,Свод!D$4,Доп.расчеты!115:115) -> 0 | E16: =-SUMIF(Доп.расчеты!$3:$3,Свод!E$4,Доп.расчеты!115:115) -> 0 | F16: =-SUMIF(Доп.расчеты!$3:$3,Свод!F$4,Доп.расчеты!115:115) -> 0 | G16: =-SUMIF(Доп.расчеты!$3:$3,Свод!G$4,Доп.расчеты!115:115) -> 0 | H16: =-SUMIF(Доп.расчеты!$3:$3,Свод!H$4,Доп.расчеты!115:115) -> 0 | I16: =-SUMIF(Доп.расчеты!$3:$3,Свод!I$4,Доп.расчеты!115:115) -> 0 | J16: =-SUMIF(Доп.расчеты!$3:$3,Свод!J$4,Доп.расчеты!115:115) -> 0 | ... M16: =-SUMIF(Доп.расчеты!$3:$3,Свод!M$4,Доп.расчеты!115:115) -> 0
B17: Производственное оборудование | C17: =-SUMIF(Доп.расчеты!$3:$3,Свод!C$4,Доп.расчеты!116:116) -> 0 | D17: =-SUMIF(Доп.расчеты!$3:$3,Свод!D$4,Доп.расчеты!116:116) -> 0 | E17: =-SUMIF(Доп.расчеты!$3:$3,Свод!E$4,Доп.расчеты!116:116) -> 0 | F17: =-SUMIF(Доп.расчеты!$3:$3,Свод!F$4,Доп.расчеты!116:116) -> 0 | G17: =-SUMIF(Доп.расчеты!$3:$3,Свод!G$4,Доп.расчеты!116:116) -> 0 | H17: =-SUMIF(Доп.расчеты!$3:$3,Свод!H$4,Доп.расчеты!116:116) -> 0 | I17: =-SUMIF(Доп.расчеты!$3:$3,Свод!I$4,Доп.расчеты!116:116) -> 0 | J17: =-SUMIF(Доп.расчеты!$3:$3,Свод!J$4,Доп.расчеты!116:116) -> 0 | ... M17: =-SUMIF(Доп.расчеты!$3:$3,Свод!M$4,Доп.расчеты!116:116) -> 0
B18: Торговое оборудование | C18: =-SUMIF(Доп.расчеты!$3:$3,Свод!C$4,Доп.расчеты!117:117) -> 0 | D18: =-SUMIF(Доп.расчеты!$3:$3,Свод!D$4,Доп.расчеты!117:117) -> 0 | E18: =-SUMIF(Доп.расчеты!$3:$3,Свод!E$4,Доп.расчеты!117:117) -> 0 | F18: =-SUMIF(Доп.расчеты!$3:$3,Свод!F$4,Доп.расчеты!117:117) -> 0 | G18: =-SUMIF(Доп.расчеты!$3:$3,Свод!G$4,Доп.расчеты!117:117) -> 0 | H18: =-SUMIF(Доп.расчеты!$3:$3,Свод!H$4,Доп.расчеты!117:117) -> 0 | I18: =-SUMIF(Доп.расчеты!$3:$3,Свод!I$4,Доп.расчеты!117:117) -> 0 | J18: =-SUMIF(Доп.расчеты!$3:$3,Свод!J$4,Доп.расчеты!117:117) -> 0 | ... M18: =-SUMIF(Доп.расчеты!$3:$3,Свод!M$4,Доп.расчеты!117:117) -> 0
B19: Складское оборудование | C19: =-SUMIF(Доп.расчеты!$3:$3,Свод!C$4,Доп.расчеты!118:118) -> 0 | D19: =-SUMIF(Доп.расчеты!$3:$3,Свод!D$4,Доп.расчеты!118:118) -> 0 | E19: =-SUMIF(Доп.расчеты!$3:$3,Свод!E$4,Доп.расчеты!118:118) -> 0 | F19: =-SUMIF(Доп.расчеты!$3:$3,Свод!F$4,Доп.расчеты!118:118) -> 0 | G19: =-SUMIF(Доп.расчеты!$3:$3,Свод!G$4,Доп.расчеты!118:118) -> 0 | H19: =-SUMIF(Доп.расчеты!$3:$3,Свод!H$4,Доп.расчеты!118:118) -> 0 | I19: =-SUMIF(Доп.расчеты!$3:$3,Свод!I$4,Доп.расчеты!118:118) -> 0 | J19: =-SUMIF(Доп.расчеты!$3:$3,Свод!J$4,Доп.расчеты!118:118) -> 0 | ... M19: =-SUMIF(Доп.расчеты!$3:$3,Свод!M$4,Доп.расчеты!118:118) -> 0
B20: Вертикальный транспорт | C20: =-SUMIF(Доп.расчеты!$3:$3,Свод!C$4,Доп.расчеты!119:119) -> 0 | D20: =-SUMIF(Доп.расчеты!$3:$3,Свод!D$4,Доп.расчеты!119:119) -> 0 | E20: =-SUMIF(Доп.расчеты!$3:$3,Свод!E$4,Доп.расчеты!119:119) -> 0 | F20: =-SUMIF(Доп.расчеты!$3:$3,Свод!F$4,Доп.расчеты!119:119) -> 0 | G20: =-SUMIF(Доп.расчеты!$3:$3,Свод!G$4,Доп.расчеты!119:119) -> 0 | H20: =-SUMIF(Доп.расчеты!$3:$3,Свод!H$4,Доп.расчеты!119:119) -> 0 | I20: =-SUMIF(Доп.расчеты!$3:$3,Свод!I$4,Доп.расчеты!119:119) -> 0 | J20: =-SUMIF(Доп.расчеты!$3:$3,Свод!J$4,Доп.расчеты!119:119) -> 0 | ... M20: =-SUMIF(Доп.расчеты!$3:$3,Свод!M$4,Доп.расчеты!119:119) -> 0
B21: Клининговое оборудование | C21: =-SUMIF(Доп.расчеты!$3:$3,Свод!C$4,Доп.расчеты!120:120) -> 0 | D21: =-SUMIF(Доп.расчеты!$3:$3,Свод!D$4,Доп.расчеты!120:120) -> 0 | E21: =-SUMIF(Доп.расчеты!$3:$3,Свод!E$4,Доп.расчеты!120:120) -> 0 | F21: =-SUMIF(Доп.расчеты!$3:$3,Свод!F$4,Доп.расчеты!120:120) -> 0 | G21: =-SUMIF(Доп.расчеты!$3:$3,Свод!G$4,Доп.расчеты!120:120) -> 0 | H21: =-SUMIF(Доп.расчеты!$3:$3,Свод!H$4,Доп.расчеты!120:120) -> 0 | I21: =-SUMIF(Доп.расчеты!$3:$3,Свод!I$4,Доп.расчеты!120:120) -> 0 | J21: =-SUMIF(Доп.расчеты!$3:$3,Свод!J$4,Доп.расчеты!120:120) -> 0 | ... M21: =-SUMIF(Доп.расчеты!$3:$3,Свод!M$4,Доп.расчеты!120:120) -> 0
B22: Офисное оборудование | C22: =-SUMIF(Доп.расчеты!$3:$3,Свод!C$4,Доп.расчеты!121:121) -> 0 | D22: =-SUMIF(Доп.расчеты!$3:$3,Свод!D$4,Доп.расчеты!121:121) -> 0 | E22: =-SUMIF(Доп.расчеты!$3:$3,Свод!E$4,Доп.расчеты!121:121) -> 0 | F22: =-SUMIF(Доп.расчеты!$3:$3,Свод!F$4,Доп.расчеты!121:121) -> 0 | G22: =-SUMIF(Доп.расчеты!$3:$3,Свод!G$4,Доп.расчеты!121:121) -> 0 | H22: =-SUMIF(Доп.расчеты!$3:$3,Свод!H$4,Доп.расчеты!121:121) -> 0 | I22: =-SUMIF(Доп.расчеты!$3:$3,Свод!I$4,Доп.расчеты!121:121) -> 0 | J22: =-SUMIF(Доп.расчеты!$3:$3,Свод!J$4,Доп.расчеты!121:121) -> 0 | ... M22: =-SUMIF(Доп.расчеты!$3:$3,Свод!M$4,Доп.расчеты!121:121) -> 0
B23: Рекламное оборудование | C23: =-SUMIF(Доп.расчеты!$3:$3,Свод!C$4,Доп.расчеты!122:122) -> 0 | D23: =-SUMIF(Доп.расчеты!$3:$3,Свод!D$4,Доп.расчеты!122:122) -> 0 | E23: =-SUMIF(Доп.расчеты!$3:$3,Свод!E$4,Доп.расчеты!122:122) -> 0 | F23: =-SUMIF(Доп.расчеты!$3:$3,Свод!F$4,Доп.расчеты!122:122) -> 0 | G23: =-SUMIF(Доп.расчеты!$3:$3,Свод!G$4,Доп.расчеты!122:122) -> 0 | H23: =-SUMIF(Доп.расчеты!$3:$3,Свод!H$4,Доп.расчеты!122:122) -> 0 | I23: =-SUMIF(Доп.расчеты!$3:$3,Свод!I$4,Доп.расчеты!122:122) -> 0 | J23: =-SUMIF(Доп.расчеты!$3:$3,Свод!J$4,Доп.расчеты!122:122) -> 0 | ... M23: =-SUMIF(Доп.расчеты!$3:$3,Свод!M$4,Доп.расчеты!122:122) -> 0
B24: ИТ оборудование | C24: =-SUMIF(Доп.расчеты!$3:$3,Свод!C$4,Доп.расчеты!123:123) -> 0 | D24: =-SUMIF(Доп.расчеты!$3:$3,Свод!D$4,Доп.расчеты!123:123) -> 0 | E24: =-SUMIF(Доп.расчеты!$3:$3,Свод!E$4,Доп.расчеты!123:123) -> 0 | F24: =-SUMIF(Доп.расчеты!$3:$3,Свод!F$4,Доп.расчеты!123:123) -> 0 | G24: =-SUMIF(Доп.расчеты!$3:$3,Свод!G$4,Доп.расчеты!123:123) -> 0 | H24: =-SUMIF(Доп.расчеты!$3:$3,Свод!H$4,Доп.расчеты!123:123) -> 0 | I24: =-SUMIF(Доп.расчеты!$3:$3,Свод!I$4,Доп.расчеты!123:123) -> 0 | J24: =-SUMIF(Доп.расчеты!$3:$3,Свод!J$4,Доп.расчеты!123:123) -> 0 | ... M24: =-SUMIF(Доп.расчеты!$3:$3,Свод!M$4,Доп.расчеты!123:123) -> 0
B25: СБ оборудование | C25: =-SUMIF(Доп.расчеты!$3:$3,Свод!C$4,Доп.расчеты!124:124) -> 0 | D25: =-SUMIF(Доп.расчеты!$3:$3,Свод!D$4,Доп.расчеты!124:124) -> 0 | E25: =-SUMIF(Доп.расчеты!$3:$3,Свод!E$4,Доп.расчеты!124:124) -> 0 | F25: =-SUMIF(Доп.расчеты!$3:$3,Свод!F$4,Доп.расчеты!124:124) -> 0 | G25: =-SUMIF(Доп.расчеты!$3:$3,Свод!G$4,Доп.расчеты!124:124) -> 0 | H25: =-SUMIF(Доп.расчеты!$3:$3,Свод!H$4,Доп.расчеты!124:124) -> 0 | I25: =-SUMIF(Доп.расчеты!$3:$3,Свод!I$4,Доп.расчеты!124:124) -> 0 | J25: =-SUMIF(Доп.расчеты!$3:$3,Свод!J$4,Доп.расчеты!124:124) -> 0 | ... M25: =-SUMIF(Доп.расчеты!$3:$3,Свод!M$4,Доп.расчеты!124:124) -> 0
B26: Прочее оборудование | C26: =-SUMIF(Доп.расчеты!$3:$3,Свод!C$4,Доп.расчеты!125:125) -> 0 | D26: =-SUMIF(Доп.расчеты!$3:$3,Свод!D$4,Доп.расчеты!125:125) -> 0 | E26: =-SUMIF(Доп.расчеты!$3:$3,Свод!E$4,Доп.расчеты!125:125) -> 0 | F26: =-SUMIF(Доп.расчеты!$3:$3,Свод!F$4,Доп.расчеты!125:125) -> 0 | G26: =-SUMIF(Доп.расчеты!$3:$3,Свод!G$4,Доп.расчеты!125:125) -> 0 | H26: =-SUMIF(Доп.расчеты!$3:$3,Свод!H$4,Доп.расчеты!125:125) -> 0 | I26: =-SUMIF(Доп.расчеты!$3:$3,Свод!I$4,Доп.расчеты!125:125) -> 0 | J26: =-SUMIF(Доп.расчеты!$3:$3,Свод!J$4,Доп.расчеты!125:125) -> 0 | ... M26: =-SUMIF(Доп.расчеты!$3:$3,Свод!M$4,Доп.расчеты!125:125) -> 0
B27: Транспорт | C27: =-SUMIF(Доп.расчеты!$3:$3,Свод!C$4,Доп.расчеты!126:126) -> 0 | D27: =-SUMIF(Доп.расчеты!$3:$3,Свод!D$4,Доп.расчеты!126:126) -> 0 | E27: =-SUMIF(Доп.расчеты!$3:$3,Свод!E$4,Доп.расчеты!126:126) -> 0 | F27: =-SUMIF(Доп.расчеты!$3:$3,Свод!F$4,Доп.расчеты!126:126) -> 0 | G27: =-SUMIF(Доп.расчеты!$3:$3,Свод!G$4,Доп.расчеты!126:126) -> 0 | H27: =-SUMIF(Доп.расчеты!$3:$3,Свод!H$4,Доп.расчеты!126:126) -> 0 | I27: =-SUMIF(Доп.расчеты!$3:$3,Свод!I$4,Доп.расчеты!126:126) -> 0 | J27: =-SUMIF(Доп.расчеты!$3:$3,Свод!J$4,Доп.расчеты!126:126) -> 0 | ... M27: =-SUMIF(Доп.расчеты!$3:$3,Свод!M$4,Доп.расчеты!126:126) -> 0
B28: Нематериальные активы | C28: =-SUMIF(Доп.расчеты!$3:$3,Свод!C$4,Доп.расчеты!127:127) -> 0 | D28: =-SUMIF(Доп.расчеты!$3:$3,Свод!D$4,Доп.расчеты!127:127) -> 0 | E28: =-SUMIF(Доп.расчеты!$3:$3,Свод!E$4,Доп.расчеты!127:127) -> 0 | F28: =-SUMIF(Доп.расчеты!$3:$3,Свод!F$4,Доп.расчеты!127:127) -> 0 | G28: =-SUMIF(Доп.расчеты!$3:$3,Свод!G$4,Доп.расчеты!127:127) -> 0 | H28: =-SUMIF(Доп.расчеты!$3:$3,Свод!H$4,Доп.расчеты!127:127) -> 0 | I28: =-SUMIF(Доп.расчеты!$3:$3,Свод!I$4,Доп.расчеты!127:127) -> 0 | J28: =-SUMIF(Доп.расчеты!$3:$3,Свод!J$4,Доп.расчеты!127:127) -> 0 | ... M28: =-SUMIF(Доп.расчеты!$3:$3,Свод!M$4,Доп.расчеты!127:127) -> 0
B29: Приобретение долей в бизнесе | C29: =-SUMIF(Доп.расчеты!$3:$3,Свод!C$4,Доп.расчеты!128:128) -> 0 | D29: =-SUMIF(Доп.расчеты!$3:$3,Свод!D$4,Доп.расчеты!128:128) -> 0 | E29: =-SUMIF(Доп.расчеты!$3:$3,Свод!E$4,Доп.расчеты!128:128) -> 0 | F29: =-SUMIF(Доп.расчеты!$3:$3,Свод!F$4,Доп.расчеты!128:128) -> 0 | G29: =-SUMIF(Доп.расчеты!$3:$3,Свод!G$4,Доп.расчеты!128:128) -> 0 | H29: =-SUMIF(Доп.расчеты!$3:$3,Свод!H$4,Доп.расчеты!128:128) -> 0 | I29: =-SUMIF(Доп.расчеты!$3:$3,Свод!I$4,Доп.расчеты!128:128) -> 0 | J29: =-SUMIF(Доп.расчеты!$3:$3,Свод!J$4,Доп.расчеты!128:128) -> 0 | ... M29: =-SUMIF(Доп.расчеты!$3:$3,Свод!M$4,Доп.расчеты!128:128) -> 0
B30: Капитализируемый ФОТ | C30: =-SUMIF(Доп.расчеты!$3:$3,Свод!C$4,Доп.расчеты!129:129) -> 0 | D30: =-SUMIF(Доп.расчеты!$3:$3,Свод!D$4,Доп.расчеты!129:129) -> 0 | E30: =-SUMIF(Доп.расчеты!$3:$3,Свод!E$4,Доп.расчеты!129:129) -> 0 | F30: =-SUMIF(Доп.расчеты!$3:$3,Свод!F$4,Доп.расчеты!129:129) -> 0 | G30: =-SUMIF(Доп.расчеты!$3:$3,Свод!G$4,Доп.расчеты!129:129) -> 0 | H30: =-SUMIF(Доп.расчеты!$3:$3,Свод!H$4,Доп.расчеты!129:129) -> 0 | I30: =-SUMIF(Доп.расчеты!$3:$3,Свод!I$4,Доп.расчеты!129:129) -> 0 | J30: =-SUMIF(Доп.расчеты!$3:$3,Свод!J$4,Доп.расчеты!129:129) -> 0 | ... M30: =-SUMIF(Доп.расчеты!$3:$3,Свод!M$4,Доп.расчеты!129:129) -> 0
B31: Консультационные услуги IT | C31: =-SUMIF(Доп.расчеты!$3:$3,Свод!C$4,Доп.расчеты!130:130) -> 0 | D31: =-SUMIF(Доп.расчеты!$3:$3,Свод!D$4,Доп.расчеты!130:130) -> 0 | E31: =-SUMIF(Доп.расчеты!$3:$3,Свод!E$4,Доп.расчеты!130:130) -> 0 | F31: =-SUMIF(Доп.расчеты!$3:$3,Свод!F$4,Доп.расчеты!130:130) -> 0 | G31: =-SUMIF(Доп.расчеты!$3:$3,Свод!G$4,Доп.расчеты!130:130) -> 0 | H31: =-SUMIF(Доп.расчеты!$3:$3,Свод!H$4,Доп.расчеты!130:130) -> 0 | I31: =-SUMIF(Доп.расчеты!$3:$3,Свод!I$4,Доп.расчеты!130:130) -> 0 | J31: =-SUMIF(Доп.расчеты!$3:$3,Свод!J$4,Доп.расчеты!130:130) -> 0 | ... M31: =-SUMIF(Доп.расчеты!$3:$3,Свод!M$4,Доп.расчеты!130:130) -> 0
B32: Тепловые завесы | C32: =-SUMIF(Доп.расчеты!$3:$3,Свод!C$4,Доп.расчеты!131:131) -> 0 | D32: =-SUMIF(Доп.расчеты!$3:$3,Свод!D$4,Доп.расчеты!131:131) -> 0 | E32: =-SUMIF(Доп.расчеты!$3:$3,Свод!E$4,Доп.расчеты!131:131) -> 0 | F32: =-SUMIF(Доп.расчеты!$3:$3,Свод!F$4,Доп.расчеты!131:131) -> 0 | G32: =-SUMIF(Доп.расчеты!$3:$3,Свод!G$4,Доп.расчеты!131:131) -> 0 | H32: =-SUMIF(Доп.расчеты!$3:$3,Свод!H$4,Доп.расчеты!131:131) -> 0 | I32: =-SUMIF(Доп.расчеты!$3:$3,Свод!I$4,Доп.расчеты!131:131) -> 0 | J32: =-SUMIF(Доп.расчеты!$3:$3,Свод!J$4,Доп.расчеты!131:131) -> 0 | ... M32: =-SUMIF(Доп.расчеты!$3:$3,Свод!M$4,Доп.расчеты!131:131) -> 0
B33: Кондиционеры и сплит-системы | C33: =-SUMIF(Доп.расчеты!$3:$3,Свод!C$4,Доп.расчеты!132:132) -> 0 | D33: =-SUMIF(Доп.расчеты!$3:$3,Свод!D$4,Доп.расчеты!132:132) -> 0 | E33: =-SUMIF(Доп.расчеты!$3:$3,Свод!E$4,Доп.расчеты!132:132) -> 0 | F33: =-SUMIF(Доп.расчеты!$3:$3,Свод!F$4,Доп.расчеты!132:132) -> 0 | G33: =-SUMIF(Доп.расчеты!$3:$3,Свод!G$4,Доп.расчеты!132:132) -> 0 | H33: =-SUMIF(Доп.расчеты!$3:$3,Свод!H$4,Доп.расчеты!132:132) -> 0 | I33: =-SUMIF(Доп.расчеты!$3:$3,Свод!I$4,Доп.расчеты!132:132) -> 0 | J33: =-SUMIF(Доп.расчеты!$3:$3,Свод!J$4,Доп.расчеты!132:132) -> 0 | ... M33: =-SUMIF(Доп.расчеты!$3:$3,Свод!M$4,Доп.расчеты!132:132) -> 0
B34: Автоматические двери и ворота | C34: =-SUMIF(Доп.расчеты!$3:$3,Свод!C$4,Доп.расчеты!133:133) -> 0 | D34: =-SUMIF(Доп.расчеты!$3:$3,Свод!D$4,Доп.расчеты!133:133) -> 0 | E34: =-SUMIF(Доп.расчеты!$3:$3,Свод!E$4,Доп.расчеты!133:133) -> 0 | F34: =-SUMIF(Доп.расчеты!$3:$3,Свод!F$4,Доп.расчеты!133:133) -> 0 | G34: =-SUMIF(Доп.расчеты!$3:$3,Свод!G$4,Доп.расчеты!133:133) -> 0 | H34: =-SUMIF(Доп.расчеты!$3:$3,Свод!H$4,Доп.расчеты!133:133) -> 0 | I34: =-SUMIF(Доп.расчеты!$3:$3,Свод!I$4,Доп.расчеты!133:133) -> 0 | J34: =-SUMIF(Доп.расчеты!$3:$3,Свод!J$4,Доп.расчеты!133:133) -> 0 | ... M34: =-SUMIF(Доп.расчеты!$3:$3,Свод!M$4,Доп.расчеты!133:133) -> 0
B35: Основная деятельность | C35: =SUM(C36:C48) -> 0 | D35: =SUM(D36:D48) -> 0 | E35: =SUM(E36:E48) -> 0 | F35: =SUM(F36:F48) -> 0 | G35: =SUM(G36:G48) -> 0 | H35: =SUM(H36:H48) -> 0 | I35: =SUM(I36:I48) -> 0 | J35: =SUM(J36:J48) -> 0 | ... M35: =SUM(M36:M48) -> 0
B36: Расходы на персонал | C36: =-SUMIF(Доп.расчеты!$3:$3,Свод!C$4,Доп.расчеты!135:135) -> 0 | D36: =-SUMIF(Доп.расчеты!$3:$3,Свод!D$4,Доп.расчеты!135:135) -> 0 | E36: =-SUMIF(Доп.расчеты!$3:$3,Свод!E$4,Доп.расчеты!135:135) -> 0 | F36: =-SUMIF(Доп.расчеты!$3:$3,Свод!F$4,Доп.расчеты!135:135) -> 0 | G36: =-SUMIF(Доп.расчеты!$3:$3,Свод!G$4,Доп.расчеты!135:135) -> 0 | H36: =-SUMIF(Доп.расчеты!$3:$3,Свод!H$4,Доп.расчеты!135:135) -> 0 | I36: =-SUMIF(Доп.расчеты!$3:$3,Свод!I$4,Доп.расчеты!135:135) -> 0 | J36: =-SUMIF(Доп.расчеты!$3:$3,Свод!J$4,Доп.расчеты!135:135) -> 0 | ... M36: =-SUMIF(Доп.расчеты!$3:$3,Свод!M$4,Доп.расчеты!135:135) -> 0
B37: Ремонт и обслуживание | C37: =-SUMIF(Доп.расчеты!$3:$3,Свод!C$4,Доп.расчеты!136:136) -> 0 | D37: =-SUMIF(Доп.расчеты!$3:$3,Свод!D$4,Доп.расчеты!136:136) -> 0 | E37: =-SUMIF(Доп.расчеты!$3:$3,Свод!E$4,Доп.расчеты!136:136) -> 0 | F37: =-SUMIF(Доп.расчеты!$3:$3,Свод!F$4,Доп.расчеты!136:136) -> 0 | G37: =-SUMIF(Доп.расчеты!$3:$3,Свод!G$4,Доп.расчеты!136:136) -> 0 | H37: =-SUMIF(Доп.расчеты!$3:$3,Свод!H$4,Доп.расчеты!136:136) -> 0 | I37: =-SUMIF(Доп.расчеты!$3:$3,Свод!I$4,Доп.расчеты!136:136) -> 0 | J37: =-SUMIF(Доп.расчеты!$3:$3,Свод!J$4,Доп.расчеты!136:136) -> 0 | ... M37: =-SUMIF(Доп.расчеты!$3:$3,Свод!M$4,Доп.расчеты!136:136) -> 0
B38: Коммунальные расходы и связь | C38: =-SUMIF(Доп.расчеты!$3:$3,Свод!C$4,Доп.расчеты!137:137) -> 0 | D38: =-SUMIF(Доп.расчеты!$3:$3,Свод!D$4,Доп.расчеты!137:137) -> 0 | E38: =-SUMIF(Доп.расчеты!$3:$3,Свод!E$4,Доп.расчеты!137:137) -> 0 | F38: =-SUMIF(Доп.расчеты!$3:$3,Свод!F$4,Доп.расчеты!137:137) -> 0 | G38: =-SUMIF(Доп.расчеты!$3:$3,Свод!G$4,Доп.расчеты!137:137) -> 0 | H38: =-SUMIF(Доп.расчеты!$3:$3,Свод!H$4,Доп.расчеты!137:137) -> 0 | I38: =-SUMIF(Доп.расчеты!$3:$3,Свод!I$4,Доп.расчеты!137:137) -> 0 | J38: =-SUMIF(Доп.расчеты!$3:$3,Свод!J$4,Доп.расчеты!137:137) -> 0 | ... M38: =-SUMIF(Доп.расчеты!$3:$3,Свод!M$4,Доп.расчеты!137:137) -> 0
B39: Расходы на охрану | C39: =-SUMIF(Доп.расчеты!$3:$3,Свод!C$4,Доп.расчеты!138:138) -> 0 | D39: =-SUMIF(Доп.расчеты!$3:$3,Свод!D$4,Доп.расчеты!138:138) -> 0 | E39: =-SUMIF(Доп.расчеты!$3:$3,Свод!E$4,Доп.расчеты!138:138) -> 0 | F39: =-SUMIF(Доп.расчеты!$3:$3,Свод!F$4,Доп.расчеты!138:138) -> 0 | G39: =-SUMIF(Доп.расчеты!$3:$3,Свод!G$4,Доп.расчеты!138:138) -> 0 | H39: =-SUMIF(Доп.расчеты!$3:$3,Свод!H$4,Доп.расчеты!138:138) -> 0 | I39: =-SUMIF(Доп.расчеты!$3:$3,Свод!I$4,Доп.расчеты!138:138) -> 0 | J39: =-SUMIF(Доп.расчеты!$3:$3,Свод!J$4,Доп.расчеты!138:138) -> 0 | ... M39: =-SUMIF(Доп.расчеты!$3:$3,Свод!M$4,Доп.расчеты!138:138) -> 0
B40: Расх материалы и хоз расходы | C40: =-SUMIF(Доп.расчеты!$3:$3,Свод!C$4,Доп.расчеты!139:139) -> 0 | D40: =-SUMIF(Доп.расчеты!$3:$3,Свод!D$4,Доп.расчеты!139:139) -> 0 | E40: =-SUMIF(Доп.расчеты!$3:$3,Свод!E$4,Доп.расчеты!139:139) -> 0 | F40: =-SUMIF(Доп.расчеты!$3:$3,Свод!F$4,Доп.расчеты!139:139) -> 0 | G40: =-SUMIF(Доп.расчеты!$3:$3,Свод!G$4,Доп.расчеты!139:139) -> 0 | H40: =-SUMIF(Доп.расчеты!$3:$3,Свод!H$4,Доп.расчеты!139:139) -> 0 | I40: =-SUMIF(Доп.расчеты!$3:$3,Свод!I$4,Доп.расчеты!139:139) -> 0 | J40: =-SUMIF(Доп.расчеты!$3:$3,Свод!J$4,Доп.расчеты!139:139) -> 0 | ... M40: =-SUMIF(Доп.расчеты!$3:$3,Свод!M$4,Доп.расчеты!139:139) -> 0
B41: Консультационные, информационные услуги и страхование | C41: =-SUMIF(Доп.расчеты!$3:$3,Свод!C$4,Доп.расчеты!140:140) -> 0 | D41: =-SUMIF(Доп.расчеты!$3:$3,Свод!D$4,Доп.расчеты!140:140) -> 0 | E41: =-SUMIF(Доп.расчеты!$3:$3,Свод!E$4,Доп.расчеты!140:140) -> 0 | F41: =-SUMIF(Доп.расчеты!$3:$3,Свод!F$4,Доп.расчеты!140:140) -> 0 | G41: =-SUMIF(Доп.расчеты!$3:$3,Свод!G$4,Доп.расчеты!140:140) -> 0 | H41: =-SUMIF(Доп.расчеты!$3:$3,Свод!H$4,Доп.расчеты!140:140) -> 0 | I41: =-SUMIF(Доп.расчеты!$3:$3,Свод!I$4,Доп.расчеты!140:140) -> 0 | J41: =-SUMIF(Доп.расчеты!$3:$3,Свод!J$4,Доп.расчеты!140:140) -> 0 | ... M41: =-SUMIF(Доп.расчеты!$3:$3,Свод!M$4,Доп.расчеты!140:140) -> 0
...

Sheet Как есть
A1: В ТЫС. РУБ. ! | B1: Дата начала проекта ----->>>>>> | C1: 46023 | D1: 46387 | E1: <<<<<<-----Дата окончания проекта | I1: =IF(($C$7/12)>H11,#REF!+1,"") | J1: =IF(($C$7/12)>I11,I1+1,"") | K1: =IF(($C$7/12)>J11,J1+1,"") | L1: =IF(($C$7/12)>K11,K1+1,"") | M1: =IF(($C$7/12)>L11,L1+1,"")
B2: 3 | C2: <-- выбор между CPI (2) и WACC (3)
C3: 2021 | D3: 2022 | E3: 2023 | F3: 2024 | G3: 2025 | H3: 2026 | I3: 2027 | J3: 2028
A4: CPI | C4: 0.04 | D4: 0.04 | E4: 0.059 | F4: 0.0811 | G4: 0.07 | H4: 0.07 | I4: 0.07 | J4: 0.05
A5: WACC monthly | C5: =IFERROR(HLOOKUP(C14,WACC_monthly!1:2,2,0),B5) -> 0.16 | D5: =IFERROR(HLOOKUP(D14,WACC_monthly!1:2,2,0),C5) -> 0.16 | E5: =IFERROR(HLOOKUP(E14,WACC_monthly!1:2,2,0),D5) -> 0.16 | F5: =IFERROR(HLOOKUP(F14,WACC_monthly!1:2,2,0),E5) -> 0.16 | G5: =IFERROR(HLOOKUP(G14,WACC_monthly!1:2,2,0),F5) -> 0.16 | H5: =IFERROR(HLOOKUP(H14,WACC_monthly!1:2,2,0),G5) -> 0.16 | I5: =IFERROR(HLOOKUP(I14,WACC_monthly!1:2,2,0),H5) -> 0.16 | J5: =IFERROR(HLOOKUP(J14,WACC_monthly!1:2,2,0),I5) -> 0.16 | ... GT5: =IFERROR(HLOOKUP(GT14,WACC_monthly!1:2,2,0),GS5) -> 0.16
A7: Срок полезного использования, мес | C7: 60
C9: =C12 -> 2026 | D9: =D12 -> 2026 | E9: =E12 -> 2026 | F9: =F12 -> 2026 | G9: =G12 -> 2026 | H9: =H12 -> 2026 | I9: =I12 -> 2026 | J9: =J12 -> 2026 | ... GT9: =GT12
C10: ='Как будет'!C10 -> 1 | D10: ='Как будет'!D10 -> 0.98770784 | E10: ='Как будет'!E10 -> 0.97556678 | F10: ='Как будет'!F10 -> 0.96357495 | G10: ='Как будет'!G10 -> 0.95173054 | H10: ='Как будет'!H10 -> 0.94003171 | I10: ='Как будет'!I10 -> 0.92847669 | J10: ='Как будет'!J10 -> 0.91706371 | ... GT10: ='Как будет'!GT10 -> 0.085324093
C11: 0 | D11: 1 | E11: =D11+1 -> 2 | F11: =E11+1 -> 3 | G11: =F11+1 -> 4 | H11: =G11+1 -> 5 | I11: =H11+1 -> 6 | J11: =I11+1 -> 7 | K11: =J11+1 -> 8 | L11: =K11+1 -> 9 | ... GT11: =GS11+1 -> 199
C12: =IFERROR(YEAR(C14),"") -> 2026 | D12: =IFERROR(YEAR(D14),"") -> 2026 | E12: =IFERROR(YEAR(E14),"") -> 2026 | F12: =IFERROR(YEAR(F14),"") -> 2026 | G12: =IFERROR(YEAR(G14),"") -> 2026 | H12: =IFERROR(YEAR(H14),"") -> 2026 | I12: =IFERROR(YEAR(I14),"") -> 2026 | J12: =IFERROR(YEAR(J14),"") -> 2026 | ... GT12: =IFERROR(YEAR(GT14),"")
C13: =IFERROR(MONTH(C14),"") -> 1 | D13: =IFERROR(MONTH(D14),"") -> 2 | E13: =IFERROR(MONTH(E14),"") -> 3 | F13: =IFERROR(MONTH(F14),"") -> 4 | G13: =IFERROR(MONTH(G14),"") -> 5 | H13: =IFERROR(MONTH(H14),"") -> 6 | I13: =IFERROR(MONTH(I14),"") -> 7 | J13: =IFERROR(MONTH(J14),"") -> 8 | ... GT13: =IFERROR(MONTH(GT14),"")
A14: AS IS | B14: Комментарии | C14: =DATE(YEAR(C1),MONTH(C1),1) -> 46023 | D14: =IF(D11>=$C$7,"",EDATE(C14,1)) -> 46054 | E14: =IF(E11>=$C$7,"",EDATE(D14,1)) -> 46082 | F14: =IF(F11>=$C$7,"",EDATE(E14,1)) -> 46113 | G14: =IF(G11>=$C$7,"",EDATE(F14,1)) -> 46143 | H14: =IF(H11>=$C$7,"",EDATE(G14,1)) -> 46174 | I14: =IF(I11>=$C$7,"",EDATE(H14,1)) -> 46204 | J14: =IF(J11>=$C$7,"",EDATE(I14,1)) -> 46235 | K14: =IF(K11>=$C$7,"",EDATE(J14,1)) -> 46266 | ... GT14: =IF(GT11>=$C$7,"",EDATE(GS14,1))
A15: Текущие расходы
A16: CAPEX | C16: =-SUM(C17:C24) -> 0 | D16: =-SUM(D17:D24) -> 0 | E16: =-SUM(E17:E24) -> 0 | F16: =-SUM(F17:F24) -> 0 | G16: =-SUM(G17:G24) -> 0 | H16: =-SUM(H17:H24) -> 0 | I16: =-SUM(I17:I24) -> 0 | J16: =-SUM(J17:J24) -> 0 | ... GT16: =-SUM(GT17:GT24) -> 0
A17: ИТ оборудование
A18: Капитализируемый ФОТ
A19: Консультационные услуги IT
A20: Нематериальные активы
A21: Производственное оборудование
A22: Рекламное оборудование
A23: Офисное оборудование
A24: Офисное оборудование
A25: Инвестиционный OPEX (вкл. Ранний старт) | C25: =SUM(C26:C33) -> 0 | D25: =SUM(D26:D33) -> 0 | E25: =SUM(E26:E33) -> 0 | F25: =SUM(F26:F33) -> 0 | G25: =SUM(G26:G33) -> 0 | H25: =SUM(H26:H33) -> 0 | I25: =SUM(I26:I33) -> 0 | J25: =SUM(J26:J33) -> 0 | ... GT25: =SUM(GT26:GT33) -> 0
A26: Расходы на персонал
A27: Расходы на персонал_Ранний старт
A28: Консультационные, информационные услуги и страхование
A29: Расходы на персонал
A30: Расходы на персонал_Ранний старт
A31: Консультационные, информационные услуги и страхование
A32: Расходы на персонал
A33: Расходы на персонал_Ранний старт
A34: OPEX | C34: =-SUM(C35:C42) -> 0 | D34: =-SUM(D35:D42) -> 0 | E34: =-SUM(E35:E42) -> 0 | F34: =-SUM(F35:F42) -> 0 | G34: =-SUM(G35:G42) -> 0 | H34: =-SUM(H35:H42) -> 0 | I34: =-SUM(I35:I42) -> 0 | J34: =-SUM(J35:J42) -> 0 | ... GT34: =-SUM(GT35:GT42) -> 0
A35: Прочие расходы
A36: Консультационные, информационные услуги и страхование
A37: Транспортные расходы
A38: Расходы на аренду
A39: Командировочные расходы
A43: Постпроектные расходы
A44: CAPEX | C44: =-SUM(C45:C52) -> 0 | D44: =-SUM(D45:D52) -> 0 | E44: =-SUM(E45:E52) -> 0 | F44: =-SUM(F45:F52) -> 0 | G44: =-SUM(G45:G52) -> 0 | H44: =-SUM(H45:H52) -> 0 | I44: =-SUM(I45:I52) -> 0 | J44: =-SUM(J45:J52) -> 0 | ... GT44: =-SUM(GT45:GT52) -> 0
A45: ИТ оборудование
...

Sheet Как будет
A1: В ТЫС. РУБ. ! | B1: Дата начала проекта ----->>>>>> | C1: ='Как есть'!C1 -> 46023 | D1: ='Как есть'!D1 -> 46387 | E1: <<<<<<-----Дата окончания проекта | I1: =IF(($C$7/12)>H11,#REF!+1,"") | J1: =IF(($C$7/12)>I11,I1+1,"") | K1: =IF(($C$7/12)>J11,J1+1,"") | L1: =IF(($C$7/12)>K11,K1+1,"") | M1: =IF(($C$7/12)>L11,L1+1,"")
B2: 3 | C2: <-- выбор между CPI (2) и WACC (3)
C3: 2021 | D3: 2022 | E3: 2023 | F3: 2024 | G3: 2025 | H3: 2026 | I3: 2027 | J3: 2028
A4: CPI | C4: 0.04 | D4: 0.04 | E4: 0.059 | F4: 0.0811 | G4: 0.07 | H4: 0.07 | I4: 0.07 | J4: 0.05
A5: WACC monthly | C5: =IFERROR(HLOOKUP(C14,WACC_monthly!1:2,2,0),'Как будет'!B5) -> 0.16 | D5: =IFERROR(HLOOKUP(D14,WACC_monthly!1:2,2,0),'Как будет'!C5) -> 0.16 | E5: =IFERROR(HLOOKUP(E14,WACC_monthly!1:2,2,0),'Как будет'!D5) -> 0.16 | F5: =IFERROR(HLOOKUP(F14,WACC_monthly!1:2,2,0),'Как будет'!E5) -> 0.16 | G5: =IFERROR(HLOOKUP(G14,WACC_monthly!1:2,2,0),'Как будет'!F5) -> 0.16 | H5: =IFERROR(HLOOKUP(H14,WACC_monthly!1:2,2,0),'Как будет'!G5) -> 0.16 | I5: =IFERROR(HLOOKUP(I14,WACC_monthly!1:2,2,0),'Как будет'!H5) -> 0.16 | J5: =IFERROR(HLOOKUP(J14,WACC_monthly!1:2,2,0),'Как будет'!I5) -> 0.16 | ... GT5: =IFERROR(HLOOKUP(GT14,WACC_monthly!1:2,2,0),'Как будет'!GS5) -> 0.16
A7: Срок полезного использования, мес | C7: ='Как есть'!C7 -> 60
C9: =C12 -> 2026 | D9: =D12 -> 2026 | E9: =E12 -> 2026 | F9: =F12 -> 2026 | G9: =G12 -> 2026 | H9: =H12 -> 2026 | I9: =I12 -> 2026 | J9: =J12 -> 2026 | ... GT9: =GT12
C10: =C113 -> 1 | D10: =D113 -> 0.98770784 | E10: =E113 -> 0.97556678 | F10: =F113 -> 0.96357495 | G10: =G113 -> 0.95173054 | H10: =H113 -> 0.94003171 | I10: =I113 -> 0.92847669 | J10: =J113 -> 0.91706371 | ... GT10: =GT113 -> 0.085324093
C11: 0 | D11: 1 | E11: =D11+1 -> 2 | F11: =E11+1 -> 3 | G11: =F11+1 -> 4 | H11: =G11+1 -> 5 | I11: =H11+1 -> 6 | J11: =I11+1 -> 7 | K11: =J11+1 -> 8 | L11: =K11+1 -> 9 | ... GT11: =GS11+1 -> 199
C12: =IFERROR(YEAR(C14),"") -> 2026 | D12: =IFERROR(YEAR(D14),"") -> 2026 | E12: =IFERROR(YEAR(E14),"") -> 2026 | F12: =IFERROR(YEAR(F14),"") -> 2026 | G12: =IFERROR(YEAR(G14),"") -> 2026 | H12: =IFERROR(YEAR(H14),"") -> 2026 | I12: =IFERROR(YEAR(I14),"") -> 2026 | J12: =IFERROR(YEAR(J14),"") -> 2026 | ... GT12: =IFERROR(YEAR(GT14),"")
C13: =IFERROR(MONTH(C14),"") -> 1 | D13: =IFERROR(MONTH(D14),"") -> 2 | E13: =IFERROR(MONTH(E14),"") -> 3 | F13: =IFERROR(MONTH(F14),"") -> 4 | G13: =IFERROR(MONTH(G14),"") -> 5 | H13: =IFERROR(MONTH(H14),"") -> 6 | I13: =IFERROR(MONTH(I14),"") -> 7 | J13: =IFERROR(MONTH(J14),"") -> 8 | ... GT13: =IFERROR(MONTH(GT14),"")
A14: TO BE | B14: Комментарии | C14: =DATE(YEAR(C1),MONTH(C1),1) -> 46023 | D14: =IF(D11>=$C$7,"",EDATE(C14,1)) -> 46054 | E14: =IF(E11>=$C$7,"",EDATE(D14,1)) -> 46082 | F14: =IF(F11>=$C$7,"",EDATE(E14,1)) -> 46113 | G14: =IF(G11>=$C$7,"",EDATE(F14,1)) -> 46143 | H14: =IF(H11>=$C$7,"",EDATE(G14,1)) -> 46174 | I14: =IF(I11>=$C$7,"",EDATE(H14,1)) -> 46204 | J14: =IF(J11>=$C$7,"",EDATE(I14,1)) -> 46235 | K14: =IF(K11>=$C$7,"",EDATE(J14,1)) -> 46266 | ... GT14: =IF(GT11>=$C$7,"",EDATE(GS14,1))
A15: Проектные расходы
A16: CАРЕХ | C16: =-SUM(C17:C24) -> -2011.36 | D16: =-SUM(D17:D24) -> -1048.44 | E16: =-SUM(E17:E24) -> -1520.3 | F16: =-SUM(F17:F24) -> -1283.74 | G16: =-SUM(G17:G24) -> -1014.92 | H16: =-SUM(H17:H24) -> -817.48 | I16: =-SUM(I17:I24) -> -817.48 | J16: =-SUM(J17:J24) -> -817.48 | ... GT16: =-SUM(GT17:GT24) -> 0
A17: Капитализируемый ФОТ | C17: 451.36 | D17: 488.44 | E17: 960.3 | F17: 723.74 | G17: 454.92 | H17: 257.48 | I17: 257.48 | J17: 257.48 | K17: 257.48 | L17: 257.48 | M17: 257.48 | N17: 164.1
A18: Консультационные услуги IT | C18: 560 | D18: 560 | E18: 560 | F18: 560 | G18: 560 | H18: 560 | I18: 560 | J18: 560 | K18: 560 | L18: 560 | M18: 560 | N18: 0
A19: Капитализируемый ФОТ
A20: ИТ оборудование | C20: 1000
A21: Нематериальные активы
A22: Консультационные услуги IT
A23: Складское оборудование
A24: Капитализируемый ФОТ
A25: Инвестиционный OPEX (вкл. Ранний старт) | C25: =-SUM(C26:C33) -> 0 | D25: =-SUM(D26:D33) -> 0 | E25: =-SUM(E26:E33) -> 0 | F25: =-SUM(F26:F33) -> 0 | G25: =-SUM(G26:G33) -> 0 | H25: =-SUM(H26:H33) -> 0 | I25: =-SUM(I26:I33) -> 0 | J25: =-SUM(J26:J33) -> 0 | ... GT25: =-SUM(GT26:GT33) -> 0
A26: Расходы на персонал
A27: Расходы на персонал_Ранний старт
A28: Консультационные, информационные услуги и страхование
A29: Расходы на персонал
A30: Расходы на персонал_Ранний старт
A31: Консультационные, информационные услуги и страхование
A32: Расходы на персонал
A33: Расходы на персонал_Ранний старт
A34: OPEX | C34: =-SUM(C35:C42) -> 0 | D34: =-SUM(D35:D42) -> 0 | E34: =-SUM(E35:E42) -> 0 | F34: =-SUM(F35:F42) -> 0 | G34: =-SUM(G35:G42) -> 0 | H34: =-SUM(H35:H42) -> 0 | I34: =-SUM(I35:I42) -> 0 | J34: =-SUM(J35:J42) -> 0 | ... GT34: =-SUM(GT35:GT42) -> 0
A35: Расходы на персонал
A36: Прочие расходы
A43: Постпроектные расходы
A44: CАРЕХ | C44: =-SUM(C45:C52) -> 0 | D44: =-SUM(D45:D52) -> 0 | E44: =-SUM(E45:E52) -> 0 | F44: =-SUM(F45:F52) -> 0 | G44: =-SUM(G45:G52) -> 0 | H44: =-SUM(H45:H52) -> 0 | I44: =-SUM(I45:I52) -> 0 | J44: =-SUM(J45:J52) -> 0 | ... GT44: =-SUM(GT45:GT52) -> 0
A45: Капитализируемый ФОТ
A46: ИТ оборудование
A47: Нематериальные активы
A48: Консультационные услуги IT
...

Sheet Доп.расчеты
B1: =IF(OR(B289<>0),1,0) -> 1 | C1: =IF(OR(C289<>0),1,0) -> 1 | D1: =IF(OR(D289<>0),1,0) -> 1 | E1: =IF(OR(E289<>0),1,0) -> 1 | F1: =IF(OR(F289<>0),1,0) -> 1 | G1: =IF(OR(G289<>0),1,0) -> 1 | H1: =IF(OR(H289<>0),1,0) -> 1 | I1: =IF(OR(I289<>0),1,0) -> 1 | ... GT1: =IF(OR(GT289<>0),1,0) -> 0
B2: =TEXT(B4,"МММГГ") -> янв26 | C2: =TEXT(C4,"МММГГ") -> февр26 | D2: =TEXT(D4,"МММГГ") -> март26 | E2: =TEXT(E4,"МММГГ") -> апр26 | F2: =TEXT(F4,"МММГГ") -> май26 | G2: =TEXT(G4,"МММГГ") -> июнь26 | H2: =TEXT(H4,"МММГГ") -> июль26 | I2: =TEXT(I4,"МММГГ") -> авг26 | ... GT2: =TEXT(GT4,"МММГГ") -> янв00
A3: Экономический эффект: | B3: ='Как есть'!C9 -> 2026 | C3: ='Как есть'!D9 -> 2026 | D3: ='Как есть'!E9 -> 2026 | E3: ='Как есть'!F9 -> 2026 | F3: ='Как есть'!G9 -> 2026 | G3: ='Как есть'!H9 -> 2026 | H3: ='Как есть'!I9 -> 2026 | I3: ='Как есть'!J9 -> 2026 | ... GT3: ='Как есть'!GU9 -> 0
A4: Себестоимость_Как есть | B4: ='Как есть'!C14 -> 46023 | C4: ='Как есть'!D14 -> 46054 | D4: ='Как есть'!E14 -> 46082 | E4: ='Как есть'!F14 -> 46113 | F4: ='Как есть'!G14 -> 46143 | G4: ='Как есть'!H14 -> 46174 | H4: ='Как есть'!I14 -> 46204 | I4: ='Как есть'!J14 -> 46235 | ... GT4: ='Как есть'!GU14 -> 0
A5: Складская логистика | B5: =SUMIF('Как есть'!$A:$A,Доп.расчеты!$A5,'Как есть'!C:C) -> 0 | C5: =SUMIF('Как есть'!$A:$A,Доп.расчеты!$A5,'Как есть'!D:D) -> 0 | D5: =SUMIF('Как есть'!$A:$A,Доп.расчеты!$A5,'Как есть'!E:E) -> 0 | E5: =SUMIF('Как есть'!$A:$A,Доп.расчеты!$A5,'Как есть'!F:F) -> 0 | F5: =SUMIF('Как есть'!$A:$A,Доп.расчеты!$A5,'Как есть'!G:G) -> 0 | G5: =SUMIF('Как есть'!$A:$A,Доп.расчеты!$A5,'Как есть'!H:H) -> 0 | H5: =SUMIF('Как есть'!$A:$A,Доп.расчеты!$A5,'Как есть'!I:I) -> 0 | I5: =SUMIF('Как есть'!$A:$A,Доп.расчеты!$A5,'Как есть'!J:J) -> 0 | J5: =SUMIF('Как есть'!$A:$A,Доп.расчеты!$A5,'Как есть'!K:K) -> 0 | K5: =SUMIF('Как есть'!$A:$A,Доп.расчеты!$A5,'Как есть'!L:L) -> 0 | L5: =SUMIF('Как есть'!$A:$A,Доп.расчеты!$A5,'Как есть'!M:M) -> 0 | M5: =SUMIF('Как есть'!$A:$A,Доп.расчеты!$A5,'Как есть'!N:N) -> 0 | N5: =SUMIF('Как есть'!$A:$A,Доп.расчеты!$A5,'Как есть'!O:O) -> 0 | O5: =SUMIF('Как есть'!$A:$A,Доп.расчеты!$A5,'Как есть'!P:P) -> 0 | P5: =SUMIF('Как есть'!$A:$A,Доп.расчеты!$A5,'Как есть'!Q:Q) -> 0 | Q5: =SUMIF('Как есть'!$A:$A,Доп.расчеты!$A5,'Как есть'!R:R) -> 0 | R5: =SUMIF('Как есть'!$A:$A,Доп.расчеты!$A5,'Как есть'!S:S) -> 0 | S5: =SUMIF('Как есть'!$A:$A,Доп.расчеты!$A5,'Как есть'!T:T) -> 0 | T5: =SUMIF('Как есть'!$A:$A,Доп.расчеты!$A5,'Как есть'!U:U) -> 0 | U5: =SUMIF('Как есть'!$A:$A,Доп.расчеты!$A5,'Как есть'!V:V) -> 0 | V5: =SUMIF('Как есть'!$A:$A,Доп.расчеты!$A5,'Как есть'!W:W) -> 0 | W5: =SUMIF('Как есть'!$A:$A,Доп.расчеты!$A5,'Как есть'!X:X) -> 0 | X5: =SUMIF('Как есть'!$A:$A,Доп.расчеты!$A5,'Как есть'!Y:Y) -> 0 | Y5: =SUMIF('Как есть'!$A:$A,Доп.расчеты!$A5,'Как есть'!Z:Z) -> 0 | Z5: =SUMIF('Как есть'!$A:$A,Доп.расчеты!$A5,'Как есть'!AA:AA) -> 0 | AA5: =SUMIF('Как есть'!$A:$A,Доп.расчеты!$A5,'Как есть'!AB:AB) -> 0 | AB5: =SUMIF('Как есть'!$A:$A,Доп.расчеты!$A5,'Как есть'!AC:AC) -> 0 | AC5: =SUMIF('Как есть'!$A:$A,Доп.расчеты!$A5,'Как есть'!AD:AD) -> 0 | AD5: =SUMIF('Как есть'!$A:$A,Доп.расчеты!$A5,'Как есть'!AE:AE) -> 0 | AE5: =SUMIF('Как есть'!$A:$A,Доп.расчеты!$A5,'Как есть'!AF:AF) -> 0 | AF5: =SUMIF('Как есть'!$A:$A,Доп.расчеты!$A5,'Как есть'!AG:AG) -> 0 | AG5: =SUMIF('Как есть'!$A:$A,Доп.расчеты!$A5,'Как есть'!AH:AH) -> 0 | AH5: =SUMIF('Как есть'!$A:$A,Доп.расчеты!$A5,'Как есть'!AI:AI) -> 0 | AI5: =SUMIF('Как есть'!$A:$A,Доп.расчеты!$A5,'Как есть'!AJ:AJ) -> 0 | AJ5: =SUMIF('Как есть'!$A:$A,Доп.расчеты!$A5,'Как есть'!AK:AK) -> 0 | AK5: =SUMIF('Как есть'!$A:$A,Доп.расчеты!$A5,'Как есть'!AL:AL) -> 0 | AL5: =SUMIF('Как есть'!$A:$A,Доп.расчеты!$A5,'Как есть'!AM:AM) -> 0 | AM5: =SUMIF('Как есть'!$A:$A,Доп.расчеты!$A5,'Как есть'!AN:AN) -> 0 | AN5: =SUMIF('Как есть'!$A:$A,Доп.расчеты!$A5,'Как есть'!AO:AO) -> 0 | AO5: =SUMIF('Как есть'!$A:$A,Доп.расчеты!$A5,'Как есть'!AP:AP) -> 0 | AP5: =SUMIF('Как есть'!$A:$A,Доп.расчеты!$A5,'Как есть'!AQ:AQ) -> 0 | AQ5: =SUMIF('Как есть'!$A:$A,Доп.расчеты!$A5,'Как есть'!AR:AR) -> 0 | AR5: =SUMIF('Как есть'!$A:$A,Доп.расчеты!$A5,'Как есть'!AS:AS) -> 0 | AS5: =SUMIF('Как есть'!$A:$A,Доп.расчеты!$A5,'Как есть'!AT:AT) -> 0 | AT5: =SUMIF('Как есть'!$A:$A,Доп.расчеты!$A5,'Как есть'!AU:AU) -> 0 | AU5: =SUMIF('Как есть'!$A:$A,Доп.расчеты!$A5,'Как есть'!AV:AV) -> 0 | AV5: =SUMIF('Как есть'!$A:$A,Доп.расчеты!$A5,'Как есть'!AW:AW) -> 0 | AW5: =SUMIF('Как есть'!$A:$A,Доп.расчеты!$A5,'Как есть'!AX:AX) -> 0 | AX5: =SUMIF('Как есть'!$A:$A,Доп.расчеты!$A5,'Как есть'!AY:AY) -> 0 | AY5: =SUMIF('Как есть'!$A:$A,Доп.расчеты!$A5,'Как есть'!AZ:AZ) -> 0 | AZ5: =SUMIF('Как есть'!$A:$A,Доп.расчеты!$A5,'Как есть'!BA:BA) -> 0 | BA5: =SUMIF('Как есть'!$A:$A,Доп.расчеты!$A5,'Как есть'!BB:BB) -> 0 | BB5: =SUMIF('Как есть'!$A:$A,Доп.расчеты!$A5,'Как есть'!BC:BC) -> 0 | BC5: =SUMIF('Как есть'!$A:$A,Доп.расчеты!$A5,'Как есть'!BD:BD) -> 0 | BD5: =SUMIF('Как есть'!$A:$A,Доп.расчеты!$A5,'Как есть'!BE:BE) -> 0 | BE5: =SUMIF('Как есть'!$A:$A,Доп.расчеты!$A5,'Как есть'!BF:BF) -> 0 | BF5: =SUMIF('Как есть'!$A:$A,Доп.расчеты!$A5,'Как есть'!BG:BG) -> 0 | BG5: =SUMIF('Как есть'!$A:$A,Доп.расчеты!$A5,'Как есть'!BH:BH) -> 0 | BH5: =SUMIF('Как есть'!$A:$A,Доп.расчеты!$A5,'Как есть'!BI:BI) -> 0 | BI5: =SUMIF('Как есть'!$A:$A,Доп.расчеты!$A5,'Как есть'!BJ:BJ) -> 0 | BJ5: =SUMIF('Как есть'!$A:$A,Доп.расчеты!$A5,'Как есть'!BK:BK) -> 0 | BK5: =SUMIF('Как есть'!$A:$A,Доп.расчеты!$A5,'Как есть'!BL:BL) -> 0 | BL5: =SUMIF('Как есть'!$A:$A,Доп.расчеты!$A5,'Как есть'!BM:BM) -> 0 | BM5: =SUMIF('Как есть'!$A:$A,Доп.расчеты!$A5,'Как есть'!BN:BN) -> 0 | BN5: =SUMIF('Как есть'!$A:$A,Доп.расчеты!$A5,'Как есть'!BO:BO) -> 0 | BO5: =SUMIF('Как есть'!$A:$A,Доп.расчеты!$A5,'Как есть'!BP:BP) -> 0 | BP5: =SUMIF('Как есть'!$A:$A,Доп.расчеты!$A5,'Как есть'!BQ:BQ) -> 0 | BQ5: =SUMIF('Как есть'!$A:$A,Доп.расчеты!$A5,'Как есть'!BR:BR) -> 0 | BR5: =SUMIF('Как есть'!$A:$A,Доп.расчеты!$A5,'Как есть'!BS:BS) -> 0 | BS5: =SUMIF('Как есть'!$A:$A,Доп.расчеты!$A5,'Как есть'!BT:BT) -> 0 | BT5: =SUMIF('Как есть'!$A:$A,Доп.расчеты!$A5,'Как есть'!BU:BU) -> 0 | BU5: =SUMIF('Как есть'!$A:$A,Доп.расчеты!$A5,'Как есть'!BV:BV) -> 0 | BV5: =SUMIF('Как есть'!$A:$A,Доп.расчеты!$A5,'Как есть'!BW:BW) -> 0 | BW5: =SUMIF('Как есть'!$A:$A,Доп.расчеты!$A5,'Как есть'!BX:BX) -> 0 | BX5: =SUMIF('Как есть'!$A:$A,Доп.расчеты!$A5,'Как есть'!BY:BY) -> 0 | BY5: =SUMIF('Как есть'!$A:$A,Доп.расчеты!$A5,'Как есть'!BZ:BZ) -> 0 | BZ5: =SUMIF('Как есть'!$A:$A,Доп.расчеты!$A5,'Как есть'!CA:CA) -> 0 | CA5: =SUMIF('Как есть'!$A:$A,Доп.расчеты!$A5,'Как есть'!CB:CB) -> 0 | CB5: =SUMIF('Как есть'!$A:$A,Доп.расчеты!$A5,'Как есть'!CC:CC) -> 0 | CC5: =SUMIF('Как есть'!$A:$A,Доп.расчеты!$A5,'Как есть'!CD:CD) -> 0 | CD5: =SUMIF('Как есть'!$A:$A,Доп.расчеты!$A5,'Как есть'!CE:CE) -> 0 | CE5: =SUMIF('Как есть'!$A:$A,Доп.расчеты!$A5,'Как есть'!CF:CF) -> 0 | CF5: =SUMIF('Как есть'!$A:$A,Доп.расчеты!$A5,'Как есть'!CG:CG) -> 0 | CG5: =SUMIF('Как есть'!$A:$A,Доп.расчеты!$A5,'Как есть'!CH:CH) -> 0 | CH5: =SUMIF('Как есть'!$A:$A,Доп.расчеты!$A5,'Как есть'!CI:CI) -> 0 | CI5: =SUMIF('Как есть'!$A:$A,Доп.расчеты!$A5,'Как есть'!CJ:CJ) -> 0 | CJ5: =SUMIF('Как есть'!$A:$A,Доп.расчеты!$A5,'Как есть'!CK:CK) -> 0 | CK5: =SUMIF('Как есть'!$A:$A,Доп.расчеты!$A5,'Как есть'!CL:CL) -> 0 | CL5: =SUMIF('Как есть'!$A:$A,Доп.расчеты!$A5,'Как есть'!CM:CM) -> 0 | CM5: =SUMIF('Как есть'!$A:$A,Доп.расчеты!$A5,'Как есть'!CN:CN) -> 0 | CN5: =SUMIF('Как есть'!$A:$A,Доп.расчеты!$A5,'Как есть'!CO:CO) -> 0 | CO5: =SUMIF('Как есть'!$A:$A,Доп.расчеты!$A5,'Как есть'!CP:CP) -> 0 | CP5: =SUMIF('Как есть'!$A:$A,Доп.расчеты!$A5,'Как есть'!CQ:CQ) -> 0 | CQ5: =SUMIF('Как есть'!$A:$A,Доп.расчеты!$A5,'Как есть'!CR:CR) -> 0 | CR5: =SUMIF('Как есть'!$A:$A,Доп.расчеты!$A5,'Как есть'!CS:CS) -> 0 | CS5: =SUMIF('Как есть'!$A:$A,Доп.расчеты!$A5,'Как есть'!CT:CT) -> 0 | CT5: =SUMIF('Как есть'!$A:$A,Доп.расчеты!$A5,'Как есть'!CU:CU) -> 0 | CU5: =SUMIF('Как есть'!$A:$A,Доп.расчеты!$A5,'Как есть'!CV:CV) -> 0 | CV5: =SUMIF('Как есть'!$A:$A,Доп.расчеты!$A5,'Как есть'!CW:CW) -> 0 | CW5: =SUMIF('Как есть'!$A:$A,Доп.расчеты!$A5,'Как есть'!CX:CX) -> 0 | CX5: =SUMIF('Как есть'!$A:$A,Доп.расчеты!$A5,'Как есть'!CY:CY) -> 0 | CY5: =SUMIF('Как есть'!$A:$A,Доп.расчеты!$A5,'Как есть'!CZ:CZ) -> 0 | CZ5: =SUMIF('Как есть'!$A:$A,Доп.расчеты!$A5,'Как есть'!DA:DA) -> 0 | DA5: =SUMIF('Как есть'!$A:$A,Доп.расчеты!$A5,'Как есть'!DB:DB) -> 0 | DB5: =SUMIF('Как есть'!$A:$A,Доп.расчеты!$A5,'Как есть'!DC:DC) -> 0 | DC5: =SUMIF('Как есть'!$A:$A,Доп.расчеты!$A5,'Как есть'!DD:DD) -> 0 | DD5: =SUMIF('Как есть'!$A:$A,Доп.расчеты!$A5,'Как есть'!DE:DE) -> 0 | DE5: =SUMIF('Как есть'!$A:$A,Доп.расчеты!$A5,'Как есть'!DF:DF) -> 0 | DF5: =SUMIF('Как есть'!$A:$A,Доп.расчеты!$A5,'Как есть'!DG:DG) -> 0 | DG5: =SUMIF('Как есть'!$A:$A,Доп.расчеты!$A5,'Как есть'!DH:DH) -> 0 | DH5: =SUMIF('Как есть'!$A:$A,Доп.расчеты!$A5,'Как есть'!DI:DI) -> 0 | DI5: =SUMIF('Как есть'!$A:$A,Доп.расчеты!$A5,'Как есть'!DJ:DJ) -> 0 | DJ5: =SUMIF('Как есть'!$A:$A,Доп.расчеты!$A5,'Как есть'!DK:DK) -> 0 | DK5: =SUMIF('Как есть'!$A:$A,Доп.расчеты!$A5,'Как есть'!DL:DL) -> 0 | DL5: =SUMIF('Как есть'!$A:$A,Доп.расчеты!$A5,'Как есть'!DM:DM) -> 0 | DM5: =SUMIF('Как есть'!$A:$A,Доп.расчеты!$A5,'Как есть'!DN:DN) -> 0 | DN5: =SUMIF('Как есть'!$A:$A,Доп.расчеты!$A5,'Как есть'!DO:DO) -> 0 | DO5: =SUMIF('Как есть'!$A:$A,Доп.расчеты!$A5,'Как есть'!DP:DP) -> 0 | DP5: =SUMIF('Как есть'!$A:$A,Доп.расчеты!$A5,'Как есть'!DQ:DQ) -> 0 | DQ5: =SUMIF('Как есть'!$A:$A,Доп.расчеты!$A5,'Как есть'!DR:DR) -> 0 | DR5: =SUMIF('Как есть'!$A:$A,Доп.расчеты!$A5,'Как есть'!DS:DS) -> 0 | DS5: =SUMIF('Как есть'!$A:$A,Доп.расчеты!$A5,'Как есть'!DT:DT) -> 0 | DT5: =SUMIF('Как есть'!$A:$A,Доп.расчеты!$A5,'Как есть'!DU:DU) -> 0 | DU5: =SUMIF('Как есть'!$A:$A,Доп.расчеты!$A5,'Как есть'!DV:DV) -> 0 | DV5: =SUMIF('Как есть'!$A:$A,Доп.расчеты!$A5,'Как есть'!DW:DW) -> 0 | DW5: =SUMIF('Как есть'!$A:$A,Доп.расчеты!$A5,'Как есть'!DX:DX) -> 0 | DX5: =SUMIF('Как есть'!$A:$A,Доп.расчеты!$A5,'Как есть'!DY:DY) -> 0 | DY5: =SUMIF('Как есть'!$A:$A,Доп.расчеты!$A5,'Как есть'!DZ:DZ) -> 0 | DZ5: =SUMIF('Как есть'!$A:$A,Доп.расчеты!$A5,'Как есть'!EA:EA) -> 0 | EA5: =SUMIF('Как есть'!$A:$A,Доп.расчеты!$A5,'Как есть'!EB:EB) -> 0 | EB5: =SUMIF('Как есть'!$A:$A,Доп.расчеты!$A5,'Как есть'!EC:EC) -> 0 | EC5: =SUMIF('Как есть'!$A:$A,Доп.расчеты!$A5,'Как есть'!ED:ED) -> 0 | ED5: =SUMIF('Как есть'!$A:$A,Доп.расчеты!$A5,'Как есть'!EE:EE) -> 0 | EE5: =SUMIF('Как есть'!$A:$A,Доп.расчеты!$A5,'Как есть'!EF:EF) -> 0 | EF5: =SUMIF('Как есть'!$A:$A,Доп.расчеты!$A5,'Как есть'!EG:EG) -> 0 | EG5: =SUMIF('Как есть'!$A:$A,Доп.расчеты!$A5,'Как есть'!EH:EH) -> 0 | EH5: =SUMIF('Как есть'!$A:$A,Доп.расчеты!$A5,'Как есть'!EI:EI) -> 0 | EI5: =SUMIF('Как есть'!$A:$A,Доп.расчеты!$A5,'Как есть'!EJ:EJ) -> 0 | EJ5: =SUMIF('Как есть'!$A:$A,Доп.расчеты!$A5,'Как есть'!EK:EK) -> 0 | EK5: =SUMIF('Как есть'!$A:$A,Доп.расчеты!$A5,'Как есть'!EL:EL) -> 0 | EL5: =SUMIF('Как есть'!$A:$A,Доп.расчеты!$A5,'Как есть'!EM:EM) -> 0 | EM5: =SUMIF('Как есть'!$A:$A,Доп.расчеты!$A5,'Как есть'!EN:EN) -> 0 | EN5: =SUMIF('Как есть'!$A:$A,Доп.расчеты!$A5,'Как есть'!EO:EO) -> 0 | EO5: =SUMIF('Как есть'!$A:$A,Доп.расчеты!$A5,'Как есть'!EP:EP) -> 0 | EP5: =SUMIF('Как есть'!$A:$A,Доп.расчеты!$A5,'Как есть'!EQ:EQ) -> 0 | EQ5: =SUMIF('Как есть'!$A:$A,Доп.расчеты!$A5,'Как есть'!ER:ER) -> 0 | ER5: =SUMIF('Как есть'!$A:$A,Доп.расчеты!$A5,'Как есть'!ES:ES) -> 0 | ES5: =SUMIF('Как есть'!$A:$A,Доп.расчеты!$A5,'Как есть'!ET:ET) -> 0 | ET5: =SUMIF('Как есть'!$A:$A,Доп.расчеты!$A5,'Как есть'!EU:EU) -> 0 | EU5: =SUMIF('Как есть'!$A:$A,Доп.расчеты!$A5,'Как есть'!EV:EV) -> 0 | EV5: =SUMIF('Как есть'!$A:$A,Доп.расчеты!$A5,'Как есть'!EW:EW) -> 0 | EW5: =SUMIF('Как есть'!$A:$A,Доп.расчеты!$A5,'Как есть'!EX:EX) -> 0 | EX5: =SUMIF('Как есть'!$A:$A,Доп.расчеты!$A5,'Как есть'!EY:EY) -> 0 | EY5: =SUMIF('Как есть'!$A:$A,Доп.расчеты!$A5,'Как есть'!EZ:EZ) -> 0 | EZ5: =SUMIF('Как есть'!$A:$A,Доп.расчеты!$A5,'Как есть'!FA:FA) -> 0 | FA5: =SUMIF('Как есть'!$A:$A,Доп.расчеты!$A5,'Как есть'!FB:FB) -> 0 | FB5: =SUMIF('Как есть'!$A:$A,Доп.расчеты!$A5,'Как есть'!FC:FC) -> 0 | FC5: =SUMIF('Как есть'!$A:$A,Доп.расчеты!$A5,'Как есть'!FD:FD) -> 0 | FD5: =SUMIF('Как есть'!$A:$A,Доп.расчеты!$A5,'Как есть'!FE:FE) -> 0 | FE5: =SUMIF('Как есть'!$A:$A,Доп.расчеты!$A5,'Как есть'!FF:FF) -> 0 | FF5: =SUMIF('Как есть'!$A:$A,Доп.расчеты!$A5,'Как есть'!FG:FG) -> 0 | FG5: =SUMIF('Как есть'!$A:$A,Доп.расчеты!$A5,'Как есть'!FH:FH) -> 0 | FH5: =SUMIF('Как есть'!$A:$A,Доп.расчеты!$A5,'Как есть'!FI:FI) -> 0 | FI5: =SUMIF('Как есть'!$A:$A,Доп.расчеты!$A5,'Как есть'!FJ:FJ) -> 0 | FJ5: =SUMIF('Как есть'!$A:$A,Доп.расчеты!$A5,'Как есть'!FK:FK) -> 0 | FK5: =SUMIF('Как есть'!$A:$A,Доп.расчеты!$A5,'Как есть'!FL:FL) -> 0 | FL5: =SUMIF('Как есть'!$A:$A,Доп.расчеты!$A5,'Как есть'!FM:FM) -> 0 | FM5: =SUMIF('Как есть'!$A:$A,Доп.расчеты!$A5,'Как есть'!FN:FN) -> 0 | FN5: =SUMIF('Как есть'!$A:$A,Доп.расчеты!$A5,'Как есть'!FO:FO) -> 0 | FO5: =SUMIF('Как есть'!$A:$A,Доп.расчеты!$A5,'Как есть'!FP:FP) -> 0 | FP5: =SUMIF('Как есть'!$A:$A,Доп.расчеты!$A5,'Как есть'!FQ:FQ) -> 0 | FQ5: =SUMIF('Как есть'!$A:$A,Доп.расчеты!$A5,'Как есть'!FR:FR) -> 0 | FR5: =SUMIF('Как есть'!$A:$A,Доп.расчеты!$A5,'Как есть'!FS:FS) -> 0 | FS5: =SUMIF('Как есть'!$A:$A,Доп.расчеты!$A5,'Как есть'!FT:FT) -> 0 | FT5: =SUMIF('Как есть'!$A:$A,Доп.расчеты!$A5,'Как есть'!FU:FU) -> 0 | FU5: =SUMIF('Как есть'!$A:$A,Доп.расчеты!$A5,'Как есть'!FV:FV) -> 0 | FV5: =SUMIF('Как есть'!$A:$A,Доп.расчеты!$A5,'Как есть'!FW:FW) -> 0 | FW5: =SUMIF('Как есть'!$A:$A,Доп.расчеты!$A5,'Как есть'!FX:FX) -> 0 | FX5: =SUMIF('Как есть'!$A:$A,Доп.расчеты!$A5,'Как есть'!FY:FY) -> 0 | FY5: =SUMIF('Как есть'!$A:$A,Доп.расчеты!$A5,'Как есть'!FZ:FZ) -> 0 | FZ5: =SUMIF('Как есть'!$A:$A,Доп.расчеты!$A5,'Как есть'!GA:GA) -> 0 | GA5: =SUMIF('Как есть'!$A:$A,Доп.расчеты!$A5,'Как есть'!GB:GB) -> 0 | GB5: =SUMIF('Как есть'!$A:$A,Доп.расчеты!$A5,'Как есть'!GC:GC) -> 0 | GC5: =SUMIF('Как есть'!$A:$A,Доп.расчеты!$A5,'Как есть'!GD:GD) -> 0 | GD5: =SUMIF('Как есть'!$A:$A,Доп.расчеты!$A5,'Как есть'!GE:GE) -> 0 | GE5: =SUMIF('Как есть'!$A:$A,Доп.расчеты!$A5,'Как есть'!GF:GF) -> 0 | GF5: =SUMIF('Как есть'!$A:$A,Доп.расчеты!$A5,'Как есть'!GG:GG) -> 0 | GG5: =SUMIF('Как есть'!$A:$A,Доп.расчеты!$A5,'Как есть'!GH:GH) -> 0 | GH5: =SUMIF('Как есть'!$A:$A,Доп.расчеты!$A5,'Как есть'!GI:GI) -> 0 | GI5: =SUMIF('Как есть'!$A:$A,Доп.расчеты!$A5,'Как есть'!GJ:GJ) -> 0 | GJ5: =SUMIF('Как есть'!$A:$A,Доп.расчеты!$A5,'Как есть'!GK:GK) -> 0 | GK5: =SUMIF('Как есть'!$A:$A,Доп.расчеты!$A5,'Как есть'!GL:GL) -> 0 | GL5: =SUMIF('Как есть'!$A:$A,Доп.расчеты!$A5,'Как есть'!GM:GM) -> 0 | GM5: =SUMIF('Как есть'!$A:$A,Доп.расчеты!$A5,'Как есть'!GN:GN) -> 0 | GN5: =SUMIF('Как есть'!$A:$A,Доп.расчеты!$A5,'Как есть'!GO:GO) -> 0 | GO5: =SUMIF('Как есть'!$A:$A,Доп.расчеты!$A5,'Как есть'!GP:GP) -> 0 | GP5: =SUMIF('Как есть'!$A:$A,Доп.расчеты!$A5,'Как есть'!GQ:GQ) -> 0 | GQ5: =SUMIF('Как есть'!$A:$A,Доп.расчеты!$A5,'Как есть'!GR:GR) -> 0 | GR5: =SUMIF('Как есть'!$A:$A,Доп.расчеты!$A5,'Как есть'!GS:GS) -> 0 | GS5: =SUMIF('Как есть'!$A:$A,Доп.расчеты!$A5,'Как есть'!GT:GT) -> 0 | GT5: =SUMIF('Как есть'!$A:$A,Доп.расчеты!$A5,'Как есть'!GU:GU) -> 0
